Workbook

Sheet README
A1: THE SOUTH AFRICA RATES LIBRARY — MASTER SHEET
A2: Library ref SA-RL-2609-01 | Base date September 2026 | Base region Gauteng | Currency ZAR
A4: WHAT THE RATES ARE
A5: Every unit rate on the Rates sheet is a NET cost build-up: labour (gang-hours x all-in gang rate) + materials (quantity incl. waste x delivered price) + sundries + plant.
A6: Net rates EXCLUDE contractor margin and EXCLUDE VAT. Column T applies the region factor and escalation; column U adds the margin on the Settings sheet (17%).
A7: VAT (15%) is added once, at the foot of the BOQ, not in the rates.
A9: HOW TO USE ON A JOB
A10: 1. Settings: pick the region from the drop-down and enter the tender / start date. Region factor and escalation flow into every rate.
A11: 2. Price the BOQ from Rates column U (sell, ex VAT) or column T (net) if the margin is applied at summary level.
A12: 3. Sanity-check the total against the Elemental sheet (AECOM R/m2 benchmarks, escalated).
A13: 4. Where the contractor supplies invoices or their own rates, overwrite the blue input cells on Materials / Labour / Plant — every rate re-builds automatically.
A15: COLOUR KEY
... A26: Replace QS ESTIMATE lines with real contractor invoice prices as SA jobs come in — the library is built to be tightened that way.

Sheet Settings
A1: SETTINGS — set per job
A3: Region (select) | B3: Gauteng (Johannesburg / Pretoria / Midrand) - BASE | C3: Drop-down. Drives the region factor.
A4: Region factor | B4: =INDEX(Regions!$B:$B,MATCH(B3,Regions!$A:$A,0)) -> 1 | C4: Looked up from Regions sheet.
A5: Library base date | B5: 46266 | C5: Resource prices current at this date.
A6: Tender / start date | B6: 46266 | C6: Enter the job's expected tender or start date.
A7: Forward escalation p.a. | B7: 0.047 | C7: BER tender-price forecast 2027 +4.7% (AECOM Cost Guide 2025/26, Section 7).
A8: Months forward | B8: =MAX(0,(YEAR(B6)-YEAR(B5))*12+MONTH(B6)-MONTH(B5)) -> 0 | C8: Formula.
A9: Escalation factor | B9: =(1+B7)^(B8/12) -> 1 | C9: Compounded from base date to tender date.
A10: Contractor margin (profit) | B10: 0.17 | C10: AI QS standing rule: 17% on all jobs.
A11: VAT | B11: 0.15 | C11: SA VAT 15% — apply at BOQ foot only.
A13: LABOUR ON-COSTS (on basic wage)
A14: Statutory (UIF 1%, SDL 1%, COIDA ~2.5%) | B14: 0.045 | C14: Unemployment Insurance Act, Skills Development Levies Act, COIDA building class estimate.
A15: Leave, public holidays, sick leave, bonus | B15: 0.14 | C15: BCEA entitlements + bargaining council bonus fund equivalent.
A16: Non-productive time, travel, PPE, small tools | B16: 0.1 | C16: QS estimate.
A17: TOTAL ON-COST | B17: =SUM(B14:B16) -> 0.285 | C17: Formula — used by Labour sheet.

Sheet Rates
A1: SOUTH AFRICA UNIT RATES — SA-RL-2609-01
A2: ="Region: "&Settings!$B$3&" | Factor "&TEXT(Settings!$B$4,"0.00")&" | Escalation "&TEXT(Settings!$B$9,"0.0000")&" | Margin "&TEXT(Settings!$B$10,"0%")&" | All rates ex VAT" -> Region: Gauteng (Johannesburg / Pretoria / Midrand) - BASE | Factor 1.00 | Escalation 1.0000 | Margin 17% | All rates ex VAT
A4: Code | B4: Description | C4: Unit | D4: Gang | E4: Gang-hrs / unit | F4: Labour R | G4: Mat 1 | H4: Qty 1 | I4: Mat 2 | J4: Qty 2 | K4: Mat 3 | L4: Qty 3 | M4: Materials R | N4: Sundries R | O4: Plant | P4: Plant qty | Q4: Plant R | R4: NET rate R (Gauteng base) | S4: NET rate R (region + escalation) | T4: SELL rate R incl margin, ex VAT
A5: PRELIMINARIES & GENERAL
A6: PR01 | B6: Site establishment & de-establishment, small works (hoarding, signage, set-up) | C6: item | D6: G-LAB | E6: 16 | F6: =IF(D6="",0,E6*INDEX(Gangs!$D:$D,MATCH(D6,Gangs!$A:$A,0))) -> 849.7448 | M6: =IF(G6="",0,H6*INDEX(Materials!$E:$E,MATCH(G6,Materials!$A:$A,0)))+IF(I6="",0,J6*INDEX(Materials!$E:$E,MATCH(I6,Materials!$A:$A,0)))+IF(K6="",0,L6*INDEX(Materials!$E:$E,MATCH(K6,Materials!$A:$A,0))) -> 0 | N6: 9500 | Q6: =IF(O6="",0,P6*INDEX(Plant!$D:$D,MATCH(O6,Plant!$A:$A,0))) -> 0 | R6: =F6+M6+N6+Q6 -> 10349.745 | S6: =R6*Settings!$B$4*Settings!$B$9 -> 10349.745 | T6: =S6*(1+Settings!$B$10) -> 12109.201
A7: PR02 | B7: Site foreman, full time | C7: week | D7: G-FMN | E7: 45 | F7: =IF(D7="",0,E7*INDEX(Gangs!$D:$D,MATCH(D7,Gangs!$A:$A,0))) -> 8673.75 | M7: =IF(G7="",0,H7*INDEX(Materials!$E:$E,MATCH(G7,Materials!$A:$A,0)))+IF(I7="",0,J7*INDEX(Materials!$E:$E,MATCH(I7,Materials!$A:$A,0)))+IF(K7="",0,L7*INDEX(Materials!$E:$E,MATCH(K7,Materials!$A:$A,0))) -> 0 | N7: 0 | Q7: =IF(O7="",0,P7*INDEX(Plant!$D:$D,MATCH(O7,Plant!$A:$A,0))) -> 0 | R7: =F7+M7+N7+Q7 -> 8673.75 | S7: =R7*Settings!$B$4*Settings!$B$9 -> 8673.75 | T7: =S7*(1+Settings!$B$10) -> 10148.288
A8: PR03 | B8: Site agent, one day per week | C8: week | D8: G-SA | E8: 9 | F8: =IF(D8="",0,E8*INDEX(Gangs!$D:$D,MATCH(D8,Gangs!$A:$A,0))) -> 2775.6 | M8: =IF(G8="",0,H8*INDEX(Materials!$E:$E,MATCH(G8,Materials!$A:$A,0)))+IF(I8="",0,J8*INDEX(Materials!$E:$E,MATCH(I8,Materials!$A:$A,0)))+IF(K8="",0,L8*INDEX(Materials!$E:$E,MATCH(K8,Materials!$A:$A,0))) -> 0 | N8: 0 | Q8: =IF(O8="",0,P8*INDEX(Plant!$D:$D,MATCH(O8,Plant!$A:$A,0))) -> 0 | R8: =F8+M8+N8+Q8 -> 2775.6 | S8: =R8*Settings!$B$4*Settings!$B$9 -> 2775.6 | T8: =S8*(1+Settings!$B$10) -> 3247.452
A9: PR04 | B9: Chemical toilet incl servicing | C9: week | F9: =IF(D9="",0,E9*INDEX(Gangs!$D:$D,MATCH(D9,Gangs!$A:$A,0))) -> 0 | M9: =IF(G9="",0,H9*INDEX(Materials!$E:$E,MATCH(G9,Materials!$A:$A,0)))+IF(I9="",0,J9*INDEX(Materials!$E:$E,MATCH(I9,Materials!$A:$A,0)))+IF(K9="",0,L9*INDEX(Materials!$E:$E,MATCH(K9,Materials!$A:$A,0))) -> 0 | N9: 0 | O9: P-TOILET | P9: 1 | Q9: =IF(O9="",0,P9*INDEX(Plant!$D:$D,MATCH(O9,Plant!$A:$A,0))) -> 650 | R9: =F9+M9+N9+Q9 -> 650 | S9: =R9*Settings!$B$4*Settings!$B$9 -> 650 | T9: =S9*(1+Settings!$B$10) -> 760.5
A10: PR05 | B10: Site office / store container | C10: week | F10: =IF(D10="",0,E10*INDEX(Gangs!$D:$D,MATCH(D10,Gangs!$A:$A,0))) -> 0 | M10: =IF(G10="",0,H10*INDEX(Materials!$E:$E,MATCH(G10,Materials!$A:$A,0)))+IF(I10="",0,J10*INDEX(Materials!$E:$E,MATCH(I10,Materials!$A:$A,0)))+IF(K10="",0,L10*INDEX(Materials!$E:$E,MATCH(K10,Materials!$A:$A,0))) -> 0 | N10: 0 | O10: P-CONT | P10: 1 | Q10: =IF(O10="",0,P10*INDEX(Plant!$D:$D,MATCH(O10,Plant!$A:$A,0))) -> 520 | R10: =F10+M10+N10+Q10 -> 520 | S10: =R10*Settings!$B$4*Settings!$B$9 -> 520 | T10: =S10*(1+Settings!$B$10) -> 608.4
A11: PR06 | B11: Temporary water & electricity (consumption) | C11: week | F11: =IF(D11="",0,E11*INDEX(Gangs!$D:$D,MATCH(D11,Gangs!$A:$A,0))) -> 0 | M11: =IF(G11="",0,H11*INDEX(Materials!$E:$E,MATCH(G11,Materials!$A:$A,0)))+IF(I11="",0,J11*INDEX(Materials!$E:$E,MATCH(I11,Materials!$A:$A,0)))+IF(K11="",0,L11*INDEX(Materials!$E:$E,MATCH(K11,Materials!$A:$A,0))) -> 0 | N11: 450 | Q11: =IF(O11="",0,P11*INDEX(Plant!$D:$D,MATCH(O11,Plant!$A:$A,0))) -> 0 | R11: =F11+M11+N11+Q11 -> 450 | S11: =R11*Settings!$B$4*Settings!$B$9 -> 450 | T11: =S11*(1+Settings!$B$10) -> 526.5
A12: PR07 | B12: Security guard, 12 h shift (Cape BIBC R495.34/day + on-costs) | C12: day | F12: =IF(D12="",0,E12*INDEX(Gangs!$D:$D,MATCH(D12,Gangs!$A:$A,0))) -> 0 | M12: =IF(G12="",0,H12*INDEX(Materials!$E:$E,MATCH(G12,Materials!$A:$A,0)))+IF(I12="",0,J12*INDEX(Materials!$E:$E,MATCH(I12,Materials!$A:$A,0)))+IF(K12="",0,L12*INDEX(Materials!$E:$E,MATCH(K12,Materials!$A:$A,0))) -> 0 | N12: 640 | Q12: =IF(O12="",0,P12*INDEX(Plant!$D:$D,MATCH(O12,Plant!$A:$A,0))) -> 0 | R12: =F12+M12+N12+Q12 -> 640 | S12: =R12*Settings!$B$4*Settings!$B$9 -> 640 | T12: =S12*(1+Settings!$B$10) -> 748.8
A13: PR08 | B13: Skip 6 m3 incl removal | C13: no | F13: =IF(D13="",0,E13*INDEX(Gangs!$D:$D,MATCH(D13,Gangs!$A:$A,0))) -> 0 | M13: =IF(G13="",0,H13*INDEX(Materials!$E:$E,MATCH(G13,Materials!$A:$A,0)))+IF(I13="",0,J13*INDEX(Materials!$E:$E,MATCH(I13,Materials!$A:$A,0)))+IF(K13="",0,L13*INDEX(Materials!$E:$E,MATCH(K13,Materials!$A:$A,0))) -> 0 | N13: 0 | O13: P-SKIP | P13: 1 | Q13: =IF(O13="",0,P13*INDEX(Plant!$D:$D,MATCH(O13,Plant!$A:$A,0))) -> 2300 | R13: =F13+M13+N13+Q13 -> 2300 | S13: =R13*Settings!$B$4*Settings!$B$9 -> 2300 | T13: =S13*(1+Settings!$B$10) -> 2691
A14: PR09 | B14: Health & Safety file, plan & baseline risk assessment (Construction Regs 2014) | C14: item | F14: =IF(D14="",0,E14*INDEX(Gangs!$D:$D,MATCH(D14,Gangs!$A:$A,0))) -> 0 | M14: =IF(G14="",0,H14*INDEX(Materials!$E:$E,MATCH(G14,Materials!$A:$A,0)))+IF(I14="",0,J14*INDEX(Materials!$E:$E,MATCH(I14,Materials!$A:$A,0)))+IF(K14="",0,L14*INDEX(Materials!$E:$E,MATCH(K14,Materials!$A:$A,0))) -> 0 | N14: 9500 | Q14: =IF(O14="",0,P14*INDEX(Plant!$D:$D,MATCH(O14,Plant!$A:$A,0))) -> 0 | R14: =F14+M14+N14+Q14 -> 9500 | S14: =R14*Settings!$B$4*Settings!$B$9 -> 9500 | T14: =S14*(1+Settings!$B$10) -> 11115
A15: PR10 | B15: Electrical Certificate of Compliance (COC) | C15: item | F15: =IF(D15="",0,E15*INDEX(Gangs!$D:$D,MATCH(D15,Gangs!$A:$A,0))) -> 0 | M15: =IF(G15="",0,H15*INDEX(Materials!$E:$E,MATCH(G15,Materials!$A:$A,0)))+IF(I15="",0,J15*INDEX(Materials!$E:$E,MATCH(I15,Materials!$A:$A,0)))+IF(K15="",0,L15*INDEX(Materials!$E:$E,MATCH(K15,Materials!$A:$A,0))) -> 0 | N15: 3200 | Q15: =IF(O15="",0,P15*INDEX(Plant!$D:$D,MATCH(O15,Plant!$A:$A,0))) -> 0 | R15: =F15+M15+N15+Q15 -> 3200 | S15: =R15*Settings!$B$4*Settings!$B$9 -> 3200 | T15: =S15*(1+Settings!$B$10) -> 3744
A16: PR11 | B16: Plumbing Certificate of Compliance (PIRB) | C16: item | F16: =IF(D16="",0,E16*INDEX(Gangs!$D:$D,MATCH(D16,Gangs!$A:$A,0))) -> 0 | M16: =IF(G16="",0,H16*INDEX(Materials!$E:$E,MATCH(G16,Materials!$A:$A,0)))+IF(I16="",0,J16*INDEX(Materials!$E:$E,MATCH(I16,Materials!$A:$A,0)))+IF(K16="",0,L16*INDEX(Materials!$E:$E,MATCH(K16,Materials!$A:$A,0))) -> 0 | N16: 1800 | Q16: =IF(O16="",0,P16*INDEX(Plant!$D:$D,MATCH(O16,Plant!$A:$A,0))) -> 0 | R16: =F16+M16+N16+Q16 -> 1800 | S16: =R16*Settings!$B$4*Settings!$B$9 -> 1800 | T16: =S16*(1+Settings!$B$10) -> 2106
A17: PR12 | B17: Setting out by land surveyor, small building | C17: item | F17: =IF(D17="",0,E17*INDEX(Gangs!$D:$D,MATCH(D17,Gangs!$A:$A,0))) -> 0 | M17: =IF(G17="",0,H17*INDEX(Materials!$E:$E,MATCH(G17,Materials!$A:$A,0)))+IF(I17="",0,J17*INDEX(Materials!$E:$E,MATCH(I17,Materials!$A:$A,0)))+IF(K17="",0,L17*INDEX(Materials!$E:$E,MATCH(K17,Materials!$A:$A,0))) -> 0 | N17: 6500 | Q17: =IF(O17="",0,P17*INDEX(Plant!$D:$D,MATCH(O17,Plant!$A:$A,0))) -> 0 | R17: =F17+M17+N17+Q17 -> 6500 | S17: =R17*Settings!$B$4*Settings!$B$9 -> 6500 | T17: =S17*(1+Settings!$B$10) -> 7605
A18: PR13 | B18: Builder's clean on completion | C18: m2 | D18: G-LAB | E18: 0.12 | F18: =IF(D18="",0,E18*INDEX(Gangs!$D:$D,MATCH(D18,Gangs!$A:$A,0))) -> 6.373086 | M18: =IF(G18="",0,H18*INDEX(Materials!$E:$E,MATCH(G18,Materials!$A:$A,0)))+IF(I18="",0,J18*INDEX(Materials!$E:$E,MATCH(I18,Materials!$A:$A,0)))+IF(K18="",0,L18*INDEX(Materials!$E:$E,MATCH(K18,Materials!$A:$A,0))) -> 0 | N18: 4 | Q18: =IF(O18="",0,P18*INDEX(Plant!$D:$D,MATCH(O18,Plant!$A:$A,0))) -> 0 | R18: =F18+M18+N18+Q18 -> 10.373086 | S18: =R18*Settings!$B$4*Settings!$B$9 -> 10.373086 | T18: =S18*(1+Settings!$B$10) -> 12.136511
A19: PR14 | B19: Frame scaffold hire | C19: m2/wk | F19: =IF(D19="",0,E19*INDEX(Gangs!$D:$D,MATCH(D19,Gangs!$A:$A,0))) -> 0 | M19: =IF(G19="",0,H19*INDEX(Materials!$E:$E,MATCH(G19,Materials!$A:$A,0)))+IF(I19="",0,J19*INDEX(Materials!$E:$E,MATCH(I19,Materials!$A:$A,0)))+IF(K19="",0,L19*INDEX(Materials!$E:$E,MATCH(K19,Materials!$A:$A,0))) -> 0 | N19: 0 | O19: P-SCAF | P19: 1 | Q19: =IF(O19="",0,P19*INDEX(Plant!$D:$D,MATCH(O19,Plant!$A:$A,0))) -> 18 | R19: =F19+M19+N19+Q19 -> 18 | S19: =R19*Settings!$B$4*Settings!$B$9 -> 18 | T19: =S19*(1+Settings!$B$10) -> 21.06
A20: PR15 | B20: Scaffold erect & dismantle | C20: m2 | D20: G-LAB | E20: 0.25 | F20: =IF(D20="",0,E20*INDEX(Gangs!$D:$D,MATCH(D20,Gangs!$A:$A,0))) -> 13.277263 | M20: =IF(G20="",0,H20*INDEX(Materials!$E:$E,MATCH(G20,Materials!$A:$A,0)))+IF(I20="",0,J20*INDEX(Materials!$E:$E,MATCH(I20,Materials!$A:$A,0)))+IF(K20="",0,L20*INDEX(Materials!$E:$E,MATCH(K20,Materials!$A:$A,0))) -> 0 | N20: 0 | Q20: =IF(O20="",0,P20*INDEX(Plant!$D:$D,MATCH(O20,Plant!$A:$A,0))) -> 0 | R20: =F20+M20+N20+Q20 -> 13.277263 | S20: =R20*Settings!$B$4*Settings!$B$9 -> 13.277263 | T20: =S20*(1+Settings!$B$10) -> 15.534397
A21: PR16 | B21: Temporary site fencing hire | C21: m/wk | F21: =IF(D21="",0,E21*INDEX(Gangs!$D:$D,MATCH(D21,Gangs!$A:$A,0))) -> 0 | M21: =IF(G21="",0,H21*INDEX(Materials!$E:$E,MATCH(G21,Materials!$A:$A,0)))+IF(I21="",0,J21*INDEX(Materials!$E:$E,MATCH(I21,Materials!$A:$A,0)))+IF(K21="",0,L21*INDEX(Materials!$E:$E,MATCH(K21,Materials!$A:$A,0))) -> 0 | N21: 0 | O21: P-FENCE | P21: 1 | Q21: =IF(O21="",0,P21*INDEX(Plant!$D:$D,MATCH(O21,Plant!$A:$A,0))) -> 12 | R21: =F21+M21+N21+Q21 -> 12 | S21: =R21*Settings!$B$4*Settings!$B$9 -> 12 | T21: =S21*(1+Settings!$B$10) -> 14.04
A22: PR17 | B22: Temporary protection to finished floors | C22: m2 | D22: G-LAB | E22: 0.05 | F22: =IF(D22="",0,E22*INDEX(Gangs!$D:$D,MATCH(D22,Gangs!$A:$A,0))) -> 2.6554525 | M22: =IF(G22="",0,H22*INDEX(Materials!$E:$E,MATCH(G22,Materials!$A:$A,0)))+IF(I22="",0,J22*INDEX(Materials!$E:$E,MATCH(I22,Materials!$A:$A,0)))+IF(K22="",0,L22*INDEX(Materials!$E:$E,MATCH(K22,Materials!$A:$A,0))) -> 0 | N22: 18 | Q22: =IF(O22="",0,P22*INDEX(Plant!$D:$D,MATCH(O22,Plant!$A:$A,0))) -> 0 | R22: =F22+M22+N22+Q22 -> 20.655452 | S22: =R22*Settings!$B$4*Settings!$B$9 -> 20.655452 | T22: =S22*(1+Settings!$B$10) -> 24.166879
A23: DEMOLITIONS & ALTERATIONS
A24: DM01 | B24: Demolish half-brick wall incl plaster, stack rubble on site | C24: m2 | D24: G-DEM | E24: 0.6 | F24: =IF(D24="",0,E24*INDEX(Gangs!$D:$D,MATCH(D24,Gangs!$A:$A,0))) -> 105.15669 | M24: =IF(G24="",0,H24*INDEX(Materials!$E:$E,MATCH(G24,Materials!$A:$A,0)))+IF(I24="",0,J24*INDEX(Materials!$E:$E,MATCH(I24,Materials!$A:$A,0)))+IF(K24="",0,L24*INDEX(Materials!$E:$E,MATCH(K24,Materials!$A:$A,0))) -> 0 | N24: 10 | Q24: =IF(O24="",0,P24*INDEX(Plant!$D:$D,MATCH(O24,Plant!$A:$A,0))) -> 0 | R24: =F24+M24+N24+Q24 -> 115.15669 | S24: =R24*Settings!$B$4*Settings!$B$9 -> 115.15669 | T24: =S24*(1+Settings!$B$10) -> 134.73333
A25: DM02 | B25: Demolish one-brick wall incl plaster | C25: m2 | D25: G-DEM | E25: 1 | F25: =IF(D25="",0,E25*INDEX(Gangs!$D:$D,MATCH(D25,Gangs!$A:$A,0))) -> 175.26115 | M25: =IF(G25="",0,H25*INDEX(Materials!$E:$E,MATCH(G25,Materials!$A:$A,0)))+IF(I25="",0,J25*INDEX(Materials!$E:$E,MATCH(I25,Materials!$A:$A,0)))+IF(K25="",0,L25*INDEX(Materials!$E:$E,MATCH(K25,Materials!$A:$A,0))) -> 0 | N25: 15 | Q25: =IF(O25="",0,P25*INDEX(Plant!$D:$D,MATCH(O25,Plant!$A:$A,0))) -> 0 | R25: =F25+M25+N25+Q25 -> 190.26115 | S25: =R25*Settings!$B$4*Settings!$B$9 -> 190.26115 | T25: =S25*(1+Settings!$B$10) -> 222.60555
A26: DM03 | B26: Break up concrete surface bed <= 100 mm | C26: m2 | D26: G-DEM | E26: 0.5 | F26: =IF(D26="",0,E26*INDEX(Gangs!$D:$D,MATCH(D26,Gangs!$A:$A,0))) -> 87.630575 | M26: =IF(G26="",0,H26*INDEX(Materials!$E:$E,MATCH(G26,Materials!$A:$A,0)))+IF(I26="",0,J26*INDEX(Materials!$E:$E,MATCH(I26,Materials!$A:$A,0)))+IF(K26="",0,L26*INDEX(Materials!$E:$E,MATCH(K26,Materials!$A:$A,0))) -> 0 | N26: 0 | O26: P-JACK | P26: 0.4 | Q26: =IF(O26="",0,P26*INDEX(Plant!$D:$D,MATCH(O26,Plant!$A:$A,0))) -> 60 | R26: =F26+M26+N26+Q26 -> 147.63057 | S26: =R26*Settings!$B$4*Settings!$B$9 -> 147.63057 | T26: =S26*(1+Settings!$B$10) -> 172.72777
A27: DM04 | B27: Break up reinforced concrete | C27: m3 | D27: G-DEM | E27: 6 | F27: =IF(D27="",0,E27*INDEX(Gangs!$D:$D,MATCH(D27,Gangs!$A:$A,0))) -> 1051.5669 | M27: =IF(G27="",0,H27*INDEX(Materials!$E:$E,MATCH(G27,Materials!$A:$A,0)))+IF(I27="",0,J27*INDEX(Materials!$E:$E,MATCH(I27,Materials!$A:$A,0)))+IF(K27="",0,L27*INDEX(Materials!$E:$E,MATCH(K27,Materials!$A:$A,0))) -> 0 | N27: 0 | O27: P-JACK | P27: 5 | Q27: =IF(O27="",0,P27*INDEX(Plant!$D:$D,MATCH(O27,Plant!$A:$A,0))) -> 750 | R27: =F27+M27+N27+Q27 -> 1801.5669 | S27: =R27*Settings!$B$4*Settings!$B$9 -> 1801.5669 | T27: =S27*(1+Settings!$B$10) -> 2107.8333
A28: DM05 | B28: Strip concrete / clay roof tiles & battens | C28: m2 | D28: G-DEM | E28: 0.25 | F28: =IF(D28="",0,E28*INDEX(Gangs!$D:$D,MATCH(D28,Gangs!$A:$A,0))) -> 43.815287 | M28: =IF(G28="",0,H28*INDEX(Materials!$E:$E,MATCH(G28,Materials!$A:$A,0)))+IF(I28="",0,J28*INDEX(Materials!$E:$E,MATCH(I28,Materials!$A:$A,0)))+IF(K28="",0,L28*INDEX(Materials!$E:$E,MATCH(K28,Materials!$A:$A,0))) -> 0 | N28: 5 | Q28: =IF(O28="",0,P28*INDEX(Plant!$D:$D,MATCH(O28,Plant!$A:$A,0))) -> 0 | R28: =F28+M28+N28+Q28 -> 48.815287 | S28: =R28*Settings!$B$4*Settings!$B$9 -> 48.815287 | T28: =S28*(1+Settings!$B$10) -> 57.113886
A29: DM06 | B29: Strip metal roof sheeting | C29: m2 | D29: G-DEM | E29: 0.15 | F29: =IF(D29="",0,E29*INDEX(Gangs!$D:$D,MATCH(D29,Gangs!$A:$A,0))) -> 26.289172 | M29: =IF(G29="",0,H29*INDEX(Materials!$E:$E,MATCH(G29,Materials!$A:$A,0)))+IF(I29="",0,J29*INDEX(Materials!$E:$E,MATCH(I29,Materials!$A:$A,0)))+IF(K29="",0,L29*INDEX(Materials!$E:$E,MATCH(K29,Materials!$A:$A,0))) -> 0 | N29: 5 | Q29: =IF(O29="",0,P29*INDEX(Plant!$D:$D,MATCH(O29,Plant!$A:$A,0))) -> 0 | R29: =F29+M29+N29+Q29 -> 31.289172 | S29: =R29*Settings!$B$4*Settings!$B$9 -> 31.289172 | T29: =S29*(1+Settings!$B$10) -> 36.608332
A30: DM07 | B30: Remove roof timbers / trusses | C30: m2 | D30: G-DEM | E30: 0.3 | F30: =IF(D30="",0,E30*INDEX(Gangs!$D:$D,MATCH(D30,Gangs!$A:$A,0))) -> 52.578345 | M30: =IF(G30="",0,H30*INDEX(Materials!$E:$E,MATCH(G30,Materials!$A:$A,0)))+IF(I30="",0,J30*INDEX(Materials!$E:$E,MATCH(I30,Materials!$A:$A,0)))+IF(K30="",0,L30*INDEX(Materials!$E:$E,MATCH(K30,Materials!$A:$A,0))) -> 0 | N30: 5 | Q30: =IF(O30="",0,P30*INDEX(Plant!$D:$D,MATCH(O30,Plant!$A:$A,0))) -> 0 | R30: =F30+M30+N30+Q30 -> 57.578345 | S30: =R30*Settings!$B$4*Settings!$B$9 -> 57.578345 | T30: =S30*(1+Settings!$B$10) -> 67.366664
A31: DM08 | B31: Remove ceiling incl brandering & cornice | C31: m2 | D31: G-DEM | E31: 0.2 | F31: =IF(D31="",0,E31*INDEX(Gangs!$D:$D,MATCH(D31,Gangs!$A:$A,0))) -> 35.05223 | M31: =IF(G31="",0,H31*INDEX(Materials!$E:$E,MATCH(G31,Materials!$A:$A,0)))+IF(I31="",0,J31*INDEX(Materials!$E:$E,MATCH(I31,Materials!$A:$A,0)))+IF(K31="",0,L31*INDEX(Materials!$E:$E,MATCH(K31,Materials!$A:$A,0))) -> 0 | N31: 5 | Q31: =IF(O31="",0,P31*INDEX(Plant!$D:$D,MATCH(O31,Plant!$A:$A,0))) -> 0 | R31: =F31+M31+N31+Q31 -> 40.05223 | S31: =R31*Settings!$B$4*Settings!$B$9 -> 40.05223 | T31: =S31*(1+Settings!$B$10) -> 46.861109
A32: DM09 | B32: Hack off wall plaster | C32: m2 | D32: G-DEM | E32: 0.35 | F32: =IF(D32="",0,E32*INDEX(Gangs!$D:$D,MATCH(D32,Gangs!$A:$A,0))) -> 61.341403 | M32: =IF(G32="",0,H32*INDEX(Materials!$E:$E,MATCH(G32,Materials!$A:$A,0)))+IF(I32="",0,J32*INDEX(Materials!$E:$E,MATCH(I32,Materials!$A:$A,0)))+IF(K32="",0,L32*INDEX(Materials!$E:$E,MATCH(K32,Materials!$A:$A,0))) -> 0 | N32: 5 | Q32: =IF(O32="",0,P32*INDEX(Plant!$D:$D,MATCH(O32,Plant!$A:$A,0))) -> 0 | R32: =F32+M32+N32+Q32 -> 66.341403 | S32: =R32*Settings!$B$4*Settings!$B$9 -> 66.341403 | T32: =S32*(1+Settings!$B$10) -> 77.619441
A33: DM10 | B33: Remove floor tiles incl screed | C33: m2 | D33: G-DEM | E33: 0.4 | F33: =IF(D33="",0,E33*INDEX(Gangs!$D:$D,MATCH(D33,Gangs!$A:$A,0))) -> 70.10446 | M33: =IF(G33="",0,H33*INDEX(Materials!$E:$E,MATCH(G33,Materials!$A:$A,0)))+IF(I33="",0,J33*INDEX(Materials!$E:$E,MATCH(I33,Materials!$A:$A,0)))+IF(K33="",0,L33*INDEX(Materials!$E:$E,MATCH(K33,Materials!$A:$A,0))) -> 0 | N33: 5 | Q33: =IF(O33="",0,P33*INDEX(Plant!$D:$D,MATCH(O33,Plant!$A:$A,0))) -> 0 | R33: =F33+M33+N33+Q33 -> 75.10446 | S33: =R33*Settings!$B$4*Settings!$B$9 -> 75.10446 | T33: =S33*(1+Settings!$B$10) -> 87.872218
A34: DM11 | B34: Remove door & frame, make good | C34: no | D34: G-DEM | E34: 1.5 | F34: =IF(D34="",0,E34*INDEX(Gangs!$D:$D,MATCH(D34,Gangs!$A:$A,0))) -> 262.89173 | M34: =IF(G34="",0,H34*INDEX(Materials!$E:$E,MATCH(G34,Materials!$A:$A,0)))+IF(I34="",0,J34*INDEX(Materials!$E:$E,MATCH(I34,Materials!$A:$A,0)))+IF(K34="",0,L34*INDEX(Materials!$E:$E,MATCH(K34,Materials!$A:$A,0))) -> 0 | N34: 60 | Q34: =IF(O34="",0,P34*INDEX(Plant!$D:$D,MATCH(O34,Plant!$A:$A,0))) -> 0 | R34: =F34+M34+N34+Q34 -> 322.89173 | S34: =R34*Settings!$B$4*Settings!$B$9 -> 322.89173 | T34: =S34*(1+Settings!$B$10) -> 377.78332
A35: DM12 | B35: Remove window & frame, make good | C35: no | D35: G-DEM | E35: 2.5 | F35: =IF(D35="",0,E35*INDEX(Gangs!$D:$D,MATCH(D35,Gangs!$A:$A,0))) -> 438.15287 | M35: =IF(G35="",0,H35*INDEX(Materials!$E:$E,MATCH(G35,Materials!$A:$A,0)))+IF(I35="",0,J35*INDEX(Materials!$E:$E,MATCH(I35,Materials!$A:$A,0)))+IF(K35="",0,L35*INDEX(Materials!$E:$E,MATCH(K35,Materials!$A:$A,0))) -> 0 | N35: 90 | Q35: =IF(O35="",0,P35*INDEX(Plant!$D:$D,MATCH(O35,Plant!$A:$A,0))) -> 0 | R35: =F35+M35+N35+Q35 -> 528.15287 | S35: =R35*Settings!$B$4*Settings!$B$9 -> 528.15287 | T35: =S35*(1+Settings!$B$10) -> 617.93886
A36: DM13 | B36: Disconnect & remove sanitary fitting, cap services | C36: no | D36: G-PLB | E36: 1 | F36: =IF(D36="",0,E36*INDEX(Gangs!$D:$D,MATCH(D36,Gangs!$A:$A,0))) -> 226.58405 | M36: =IF(G36="",0,H36*INDEX(Materials!$E:$E,MATCH(G36,Materials!$A:$A,0)))+IF(I36="",0,J36*INDEX(Materials!$E:$E,MATCH(I36,Materials!$A:$A,0)))+IF(K36="",0,L36*INDEX(Materials!$E:$E,MATCH(K36,Materials!$A:$A,0))) -> 0 | N36: 40 | Q36: =IF(O36="",0,P36*INDEX(Plant!$D:$D,MATCH(O36,Plant!$A:$A,0))) -> 0 | R36: =F36+M36+N36+Q36 -> 266.58405 | S36: =R36*Settings!$B$4*Settings!$B$9 -> 266.58405 | T36: =S36*(1+Settings!$B$10) -> 311.90334
A37: DM14 | B37: Form opening <= 1.0 m wide in one-brick wall incl precast lintels, make good | C37: no | D37: G-BRK | E37: 8 | F37: =IF(D37="",0,E37*INDEX(Gangs!$D:$D,MATCH(D37,Gangs!$A:$A,0))) -> 1328.9984 | G37: LINT | H37: 3 | I37: MORT | J37: 0.02 | M37: =IF(G37="",0,H37*INDEX(Materials!$E:$E,MATCH(G37,Materials!$A:$A,0)))+IF(I37="",0,J37*INDEX(Materials!$E:$E,MATCH(I37,Materials!$A:$A,0)))+IF(K37="",0,L37*INDEX(Materials!$E:$E,MATCH(K37,Materials!$A:$A,0))) -> 256.96 | N37: 150 | Q37: =IF(O37="",0,P37*INDEX(Plant!$D:$D,MATCH(O37,Plant!$A:$A,0))) -> 0 | R37: =F37+M37+N37+Q37 -> 1735.9584 | S37: =R37*Settings!$B$4*Settings!$B$9 -> 1735.9584 | T37: =S37*(1+Settings!$B$10) -> 2031.0713
A38: DM15 | B38: Form opening <= 1.0 m wide in half-brick wall incl lintel, make good | C38: no | D38: G-BRK | E38: 5 | F38: =IF(D38="",0,E38*INDEX(Gangs!$D:$D,MATCH(D38,Gangs!$A:$A,0))) -> 830.624 | G38: LINT | H38: 1.5 | I38: MORT | J38: 0.01 | M38: =IF(G38="",0,H38*INDEX(Materials!$E:$E,MATCH(G38,Materials!$A:$A,0)))+IF(I38="",0,J38*INDEX(Materials!$E:$E,MATCH(I38,Materials!$A:$A,0)))+IF(K38="",0,L38*INDEX(Materials!$E:$E,MATCH(K38,Materials!$A:$A,0))) -> 128.48 | N38: 100 | Q38: =IF(O38="",0,P38*INDEX(Plant!$D:$D,MATCH(O38,Plant!$A:$A,0))) -> 0 | R38: =F38+M38+N38+Q38 -> 1059.104 | S38: =R38*Settings!$B$4*Settings!$B$9 -> 1059.104 | T38: =S38*(1+Settings!$B$10) -> 1239.1517
A39: DM16 | B39: Needle & prop loadbearing wall for new opening (props hire allowance) | C39: no | D39: G-BRK | E39: 6 | F39: =IF(D39="",0,E39*INDEX(Gangs!$D:$D,MATCH(D39,Gangs!$A:$A,0))) -> 996.7488 | M39: =IF(G39="",0,H39*INDEX(Materials!$E:$E,MATCH(G39,Materials!$A:$A,0)))+IF(I39="",0,J39*INDEX(Materials!$E:$E,MATCH(I39,Materials!$A:$A,0)))+IF(K39="",0,L39*INDEX(Materials!$E:$E,MATCH(K39,Materials!$A:$A,0))) -> 0 | N39: 850 | Q39: =IF(O39="",0,P39*INDEX(Plant!$D:$D,MATCH(O39,Plant!$A:$A,0))) -> 0 | R39: =F39+M39+N39+Q39 -> 1846.7488 | S39: =R39*Settings!$B$4*Settings!$B$9 -> 1846.7488 | T39: =S39*(1+Settings!$B$10) -> 2160.6961
A40: DM17 | B40: Load & cart rubble to licensed tip incl tip fees | C40: m3 | D40: G-LAB | E40: 0.5 | F40: =IF(D40="",0,E40*INDEX(Gangs!$D:$D,MATCH(D40,Gangs!$A:$A,0))) -> 26.554525 | M40: =IF(G40="",0,H40*INDEX(Materials!$E:$E,MATCH(G40,Materials!$A:$A,0)))+IF(I40="",0,J40*INDEX(Materials!$E:$E,MATCH(I40,Materials!$A:$A,0)))+IF(K40="",0,L40*INDEX(Materials!$E:$E,MATCH(K40,Materials!$A:$A,0))) -> 0 | N40: 0 | O40: P-CARTRUB | P40: 1 | Q40: =IF(O40="",0,P40*INDEX(Plant!$D:$D,MATCH(O40,Plant!$A:$A,0))) -> 380 | R40: =F40+M40+N40+Q40 -> 406.55453 | S40: =R40*Settings!$B$4*Settings!$B$9 -> 406.55453 | T40: =S40*(1+Settings!$B$10) -> 475.66879
A41: EARTHWORKS
...

Sheet Materials
A1: Code | B1: Category | C1: Description | D1: Unit | E1: Price ex VAT (R) | F1: Basis | G1: Source / note
A2: CEM | B2: Aggregates & binders | C2: Cement CEM II 42.5N, 50 kg bag | D2: bag | E2: 98 | F2: MARKET | G2: Gauteng R95-R120 incl VAT (handyman JHB 2026 guide)
A3: LIME | B3: Aggregates & binders | C3: Builders lime, 25 kg bag | D3: bag | E3: 72 | F3: QS ESTIMATE
A4: BSAND | B4: Aggregates & binders | C4: Building sand, delivered | D4: m3 | E4: 420 | F4: MARKET | G4: R350-R550/m3 (JHB 2026 guide)
A5: PSAND | B5: Aggregates & binders | C5: Plaster sand, delivered | D5: m3 | E5: 390 | F5: MARKET | G5: R300-R450/m3
A6: RSAND | B6: Aggregates & binders | C6: River / concrete sand, delivered | D6: m3 | E6: 480 | F6: MARKET | G6: Premium over building sand
A7: STONE19 | B7: Aggregates & binders | C7: 19 mm crushed stone, delivered | D7: m3 | E7: 560 | F7: MARKET | G7: R400-R700/m3
A8: G5 | B8: Aggregates & binders | C8: Imported G5 selected fill, delivered | D8: m3 | E8: 300 | F8: QS ESTIMATE
A9: MORT | B9: Composites | C9: Class II mortar 1:4 (7 bags cement + 1.1 m3 building sand) | D9: m3 | E9: =7*E2+1.1*E4 -> 1148 | F9: COMPOSITE | G9: Formula
A10: PLASMIX | B10: Composites | C10: Plaster 1:5 (6 bags cement + 1.15 m3 plaster sand) | D10: m3 | E10: =6*E2+1.15*E5 -> 1036.5 | F10: COMPOSITE | G10: Formula
A11: CSITE | B11: Composites | C11: Site-mixed 25 MPa concrete (7 bags + 0.65 sand + 0.75 stone) — PPC ~6.7 bags/m3 for 20-29 MPa | D11: m3 | E11: =7*E2+0.65*E6+0.75*E7 -> 1418 | F11: COMPOSITE | G11: Formula; PPC mix guidance
A12: SCREEDMIX | B12: Composites | C12: Screed 1:4 (8 bags cement + 1.1 m3 river sand) | D12: m3 | E12: =8*E2+1.1*E6 -> 1312 | F12: COMPOSITE | G12: Formula
A13: RM15 | B13: Concrete | C13: Readymix 15 MPa / 19 mm, delivered (full loads) | D13: m3 | E13: 1520 | F13: QS ESTIMATE | G13: Readymix R1,200-R1,800/m3 market range
A14: RM20 | B14: Concrete | C14: Readymix 20 MPa | D14: m3 | E14: 1600 | F14: QS ESTIMATE
A15: RM25 | B15: Concrete | C15: Readymix 25 MPa | D15: m3 | E15: 1690 | F15: QS ESTIMATE
A16: RM30 | B16: Concrete | C16: Readymix 30 MPa | D16: m3 | E16: 1800 | F16: QS ESTIMATE
A17: RM35 | B17: Concrete | C17: Readymix 35 MPa | D17: m3 | E17: 1930 | F17: QS ESTIMATE
A18: REBAR | B18: Reinforcement | C18: High-yield Y-bar, scheduled, cut & bent, delivered | D18: t | E18: 19800 | F18: QS ESTIMATE
A19: REBARMS | B19: Reinforcement | C19: Mild steel R-bar, cut & bent, delivered | D19: t | E19: 19200 | F19: QS ESTIMATE
A20: MESH193 | B20: Reinforcement | C20: Fabric mesh Ref 193 | D20: m2 | E20: 52 | F20: QS ESTIMATE
A21: MESH245 | B21: Reinforcement | C21: Fabric mesh Ref 245 | D21: m2 | E21: 66 | F21: QS ESTIMATE
A22: MESH100 | B22: Reinforcement | C22: Fabric mesh Ref 100 | D22: m2 | E22: 31 | F22: QS ESTIMATE
A23: TIEW | B23: Reinforcement | C23: Binding wire | D23: kg | E23: 42 | F23: QS ESTIMATE
A24: FWMAT | B24: Formwork | C24: Formwork materials (18 mm shutter ply + timber, 4 uses) | D24: m2 | E24: 88 | F24: QS ESTIMATE
A25: DPM250 | B25: Concrete | C25: 250 micron DPM (SANS 952) | D25: m2 | E25: 7.5 | F25: QS ESTIMATE
... A28: RIBBLK | B28: Concrete | C28: Rib-and-block suspended slab system (beams + blocks, excl topping) | D28: m2 | E28: 380 | F28: QS ESTIMATE
A29: BRKCLAY | B29: Masonry | C29: Clay stock brick NFP 222x106x73 | D29: no | E29: 2.2 | F29: MARKET | G29: R1,600-R2,500 per 1,000
A30: BRKCEM | B30: Masonry | C30: Cement stock brick NFX | D30: no | E30: 2.1 | F30: MARKET | G30: R1,800-R3,000 per 1,000
A31: FACEBRK | B31: Masonry | C31: Clay face brick (PC) | D31: no | E31: 5.4 | F31: MARKET | G31: R3,500-R6,000 per 1,000
A32: BLK90 | B32: Masonry | C32: Cement block 390x190x90 | D32: no | E32: 9.8 | F32: QS ESTIMATE
A33: BLK140 | B33: Masonry | C33: Cement block 390x190x140 | D33: no | E33: 13.5 | F33: QS ESTIMATE
A34: BLK190 | B34: Masonry | C34: Cement block 390x190x190 | D34: no | E34: 17.9 | F34: QS ESTIMATE
A35: BFORCE | B35: Masonry | C35: Brickforce 150 mm | D35: m | E35: 3.1 | F35: QS ESTIMATE
A36: TIES | B36: Masonry | C36: Galvanised wire wall tie | D36: no | E36: 1.6 | F36: QS ESTIMATE
A37: DPC375 | B37: Masonry | C37: Embossed polyolefin DPC 375 mm | D37: m | E37: 7.5 | F37: QS ESTIMATE
A38: DPC230 | B38: Masonry | C38: Embossed polyolefin DPC 230 mm | D38: m | E38: 4.6 | F38: QS ESTIMATE
A39: HOOP | B39: Masonry | C39: Galvanised hoop iron 30x1.6 | D39: m | E39: 4.5 | F39: QS ESTIMATE
A40: TRUSS | B40: Roofing | C40: Engineered timber trusses incl hangers & bracing, delivered (per m2 plan) | D40: m2 | E40: 330 | F40: QS ESTIMATE | G40: Truss cost R250-R650/m2 excl covering (Complete Roofing 2026)
A41: TIM114 | B41: Roofing | C41: SA pine S5 38x114 | D41: m | E41: 44 | F41: QS ESTIMATE
A42: TIM152 | B42: Roofing | C42: SA pine S5 38x152 | D42: m | E42: 60 | F42: QS ESTIMATE
...

Sheet Labour
A1: Code | B1: Grade / trade | C1: Basic wage R/hr | D1: Basis | E1: Source | F1: On-cost % | G1: All-in R/hr | H1: All-in R/day (9 h)
A2: L01 | B2: Labourer | C2: 41.33 | D2: PUBLISHED | E2: Cape Building Industry Bargaining Council main agreement, cl.18 (to 31 Oct 2026); BCCEI Grade 1 R41.72 | F2: =Settings!$B$17 -> 0.285 | G2: =C2*(1+F2) -> 53.10905 | H2: =G2*9 -> 477.98145
A3: L02 | B3: General worker (semi-skilled) | C3: 53.73 | D3: PUBLISHED | E3: Cape BIBC cl.18 | F3: =Settings!$B$17 -> 0.285 | G3: =C3*(1+F3) -> 69.04305 | H3: =G3*9 -> 621.38745
A4: L03 | B4: Tradesman Class 4 | C4: 58.49 | D4: PUBLISHED | E4: Cape BIBC cl.18 | F4: =Settings!$B$17 -> 0.285 | G4: =C4*(1+F4) -> 75.15965 | H4: =G4*9 -> 676.43685
A5: L04 | B5: Tradesman Class 3 (painter, paver, waterproofer) | C5: 64.52 | D5: PUBLISHED | E5: Cape BIBC cl.18 | F5: =Settings!$B$17 -> 0.285 | G5: =C5*(1+F5) -> 82.9082 | H5: =G5*9 -> 746.1738
A6: L05 | B6: Tradesman Class 2 (bricklayer, plasterer, tiler, shutterhand) | C6: 87.95 | D6: PUBLISHED | E6: Cape BIBC cl.18 | F6: =Settings!$B$17 -> 0.285 | G6: =C6*(1+F6) -> 113.01575 | H6: =G6*9 -> 1017.1418
A7: L06 | B7: Artisan (qualified carpenter / joiner / welder) | C7: 117.23 | D7: PUBLISHED | E7: Cape BIBC cl.18 | F7: =Settings!$B$17 -> 0.285 | G7: =C7*(1+F7) -> 150.64055 | H7: =G7*9 -> 1355.7649
A8: L07 | B8: Plant operator / driver Code C1 | C8: 73.41 | D8: PUBLISHED | E8: Cape BIBC cl.18 | F8: =Settings!$B$17 -> 0.285 | G8: =C8*(1+F8) -> 94.33185 | H8: =G8*9 -> 848.98665
A9: L08 | B9: Driver Code B | C9: 55.28 | D9: PUBLISHED | E9: Cape BIBC cl.18 | F9: =Settings!$B$17 -> 0.285 | G9: =C9*(1+F9) -> 71.0348 | H9: =G9*9 -> 639.3132
A10: L09 | B10: Electrician (registered, can issue COC) | C10: 140 | D10: QS ESTIMATE | E10: Market employed rate, 2026 | F10: =Settings!$B$17 -> 0.285 | G10: =C10*(1+F10) -> 179.9 | H10: =G10*9 -> 1619.1
A11: L10 | B11: Plumber (PIRB registered) | C11: 135 | D11: QS ESTIMATE | E11: Market employed rate, 2026 | F11: =Settings!$B$17 -> 0.285 | G11: =C11*(1+F11) -> 173.475 | H11: =G11*9 -> 1561.275
A12: L11 | B12: Site foreman | C12: 150 | D12: QS ESTIMATE | E12: Market, small-medium builder | F12: =Settings!$B$17 -> 0.285 | G12: =C12*(1+F12) -> 192.75 | H12: =G12*9 -> 1734.75
A13: L12 | B13: Site agent / contracts manager | C13: 240 | D13: QS ESTIMATE | E13: Market, small-medium builder | F13: =Settings!$B$17 -> 0.285 | G13: =C13*(1+F13) -> 308.4 | H13: =G13*9 -> 2775.6
A15: Reference: National Minimum Wage R30.23/hr from 1 March 2026 (GN R.7083, Gazette 54075). Bargaining council minima above sit higher and apply to formal building employers.
A16: Security guard (Cape BIBC) R495.34 per day basic — used in Preliminaries.

Sheet Gangs
A1: Gang | B1: Description | C1: Composition | D1: R per gang-hour
A2: G-LAB | B2: Labourer | C2: 1 x L01 | D2: =1*INDEX(Labour!$G:$G,MATCH("L01",Labour!$A:$A,0)) -> 53.10905
A3: G-SEM | B3: Semi-skilled general worker | C3: 1 x L02 | D3: =1*INDEX(Labour!$G:$G,MATCH("L02",Labour!$A:$A,0)) -> 69.04305
A4: G-DEM | B4: Demolition / strip-out gang | C4: 1 x L02 + 2 x L01 | D4: =1*INDEX(Labour!$G:$G,MATCH("L02",Labour!$A:$A,0))+2*INDEX(Labour!$G:$G,MATCH("L01",Labour!$A:$A,0)) -> 175.26115
A5: G-BRK | B5: Bricklayer + attendant | C5: 1 x L05 + 1 x L01 | D5: =1*INDEX(Labour!$G:$G,MATCH("L05",Labour!$A:$A,0))+1*INDEX(Labour!$G:$G,MATCH("L01",Labour!$A:$A,0)) -> 166.1248
A6: G-BRKF | B6: Face-brick artisan + attendant | C6: 1 x L06 + 1 x L01 | D6: =1*INDEX(Labour!$G:$G,MATCH("L06",Labour!$A:$A,0))+1*INDEX(Labour!$G:$G,MATCH("L01",Labour!$A:$A,0)) -> 203.7496
A7: G-CON | B7: Concrete gang | C7: 1 x L05 + 1 x L02 + 2 x L01 | D7: =1*INDEX(Labour!$G:$G,MATCH("L05",Labour!$A:$A,0))+1*INDEX(Labour!$G:$G,MATCH("L02",Labour!$A:$A,0))+2*INDEX(Labour!$G:$G,MATCH("L01",Labour!$A:$A,0)) -> 288.2769
A8: G-SHT | B8: Shutterhand + labourer | C8: 1 x L05 + 1 x L01 | D8: =1*INDEX(Labour!$G:$G,MATCH("L05",Labour!$A:$A,0))+1*INDEX(Labour!$G:$G,MATCH("L01",Labour!$A:$A,0)) -> 166.1248
A9: G-STF | B9: Steel fixer + labourer | C9: 1 x L05 + 1 x L01 | D9: =1*INDEX(Labour!$G:$G,MATCH("L05",Labour!$A:$A,0))+1*INDEX(Labour!$G:$G,MATCH("L01",Labour!$A:$A,0)) -> 166.1248
A10: G-CRP | B10: Carpenter + labourer | C10: 1 x L06 + 1 x L01 | D10: =1*INDEX(Labour!$G:$G,MATCH("L06",Labour!$A:$A,0))+1*INDEX(Labour!$G:$G,MATCH("L01",Labour!$A:$A,0)) -> 203.7496
A11: G-JNR | B11: Joiner | C11: 1 x L06 | D11: =1*INDEX(Labour!$G:$G,MATCH("L06",Labour!$A:$A,0)) -> 150.64055
A12: G-RFR | B12: Roofer + labourer | C12: 1 x L05 + 1 x L01 | D12: =1*INDEX(Labour!$G:$G,MATCH("L05",Labour!$A:$A,0))+1*INDEX(Labour!$G:$G,MATCH("L01",Labour!$A:$A,0)) -> 166.1248
A13: G-PLS | B13: Plasterer + labourer | C13: 1 x L05 + 1 x L01 | D13: =1*INDEX(Labour!$G:$G,MATCH("L05",Labour!$A:$A,0))+1*INDEX(Labour!$G:$G,MATCH("L01",Labour!$A:$A,0)) -> 166.1248
A14: G-SCR | B14: Screeder / finisher + labourer | C14: 1 x L05 + 1 x L01 | D14: =1*INDEX(Labour!$G:$G,MATCH("L05",Labour!$A:$A,0))+1*INDEX(Labour!$G:$G,MATCH("L01",Labour!$A:$A,0)) -> 166.1248
A15: G-TIL | B15: Tiler + half labourer | C15: 1 x L05 + 0.5 x L01 | D15: =1*INDEX(Labour!$G:$G,MATCH("L05",Labour!$A:$A,0))+0.5*INDEX(Labour!$G:$G,MATCH("L01",Labour!$A:$A,0)) -> 139.57028
A16: G-DRY | B16: Ceiling / drywall fixer + half worker | C16: 1 x L05 + 0.5 x L02 | D16: =1*INDEX(Labour!$G:$G,MATCH("L05",Labour!$A:$A,0))+0.5*INDEX(Labour!$G:$G,MATCH("L02",Labour!$A:$A,0)) -> 147.53727
A17: G-PNT | B17: Painter | C17: 1 x L04 | D17: =1*INDEX(Labour!$G:$G,MATCH("L04",Labour!$A:$A,0)) -> 82.9082
A18: G-WPF | B18: Waterproofer + labourer | C18: 1 x L04 + 1 x L01 | D18: =1*INDEX(Labour!$G:$G,MATCH("L04",Labour!$A:$A,0))+1*INDEX(Labour!$G:$G,MATCH("L01",Labour!$A:$A,0)) -> 136.01725
A19: G-GLZ | B19: Glazier / fixer | C19: 1 x L05 | D19: =1*INDEX(Labour!$G:$G,MATCH("L05",Labour!$A:$A,0)) -> 113.01575
A20: G-STW | B20: Steel erector gang | C20: 1 x L06 + 1 x L02 + 1 x L01 | D20: =1*INDEX(Labour!$G:$G,MATCH("L06",Labour!$A:$A,0))+1*INDEX(Labour!$G:$G,MATCH("L02",Labour!$A:$A,0))+1*INDEX(Labour!$G:$G,MATCH("L01",Labour!$A:$A,0)) -> 272.79265
A21: G-PLB | B21: Plumber + labourer | C21: 1 x L10 + 1 x L01 | D21: =1*INDEX(Labour!$G:$G,MATCH("L10",Labour!$A:$A,0))+1*INDEX(Labour!$G:$G,MATCH("L01",Labour!$A:$A,0)) -> 226.58405
A22: G-ELE | B22: Electrician + assistant | C22: 1 x L09 + 1 x L02 | D22: =1*INDEX(Labour!$G:$G,MATCH("L09",Labour!$A:$A,0))+1*INDEX(Labour!$G:$G,MATCH("L02",Labour!$A:$A,0)) -> 248.94305
A23: G-PAV | B23: Paving gang | C23: 1 x L04 + 2 x L01 | D23: =1*INDEX(Labour!$G:$G,MATCH("L04",Labour!$A:$A,0))+2*INDEX(Labour!$G:$G,MATCH("L01",Labour!$A:$A,0)) -> 189.1263
A24: G-FMN | B24: Site foreman | C24: 1 x L11 | D24: =1*INDEX(Labour!$G:$G,MATCH("L11",Labour!$A:$A,0)) -> 192.75
A25: G-SA | B25: Site agent | C25: 1 x L12 | D25: =1*INDEX(Labour!$G:$G,MATCH("L12",Labour!$A:$A,0)) -> 308.4

Sheet Plant
A1: Code | B1: Description | C1: Unit | D1: Rate ex VAT (R) | E1: Basis
A2: P-TLB | B2: TLB with operator & fuel | C2: hr | D2: 520 | E2: QS ESTIMATE
A3: P-EXC20 | B3: 20 t excavator with operator & fuel | C3: hr | D3: 1050 | E3: QS ESTIMATE
A4: P-JACK | B4: Compressor + jackhammer / breaker | C4: hr | D4: 150 | E4: QS ESTIMATE
A5: P-PLATE | B5: Plate compactor | C5: day | D5: 380 | E5: QS ESTIMATE
A6: P-ROLLER | B6: 1 t vibratory roller | C6: day | D6: 1400 | E6: QS ESTIMATE
A7: P-POKER | B7: Poker vibrator | C7: day | D7: 320 | E7: QS ESTIMATE
A8: P-MIXER | B8: 150 L concrete mixer | C8: day | D8: 300 | E8: QS ESTIMATE
A9: P-FLOAT | B9: Power float | C9: day | D9: 600 | E9: QS ESTIMATE
A10: P-SAW | B10: Floor saw | C10: day | D10: 700 | E10: QS ESTIMATE
A11: P-GRINDER | B11: Floor grinder | C11: day | D11: 1200 | E11: QS ESTIMATE
A12: P-CPUMP | B12: Concrete pump (per m3 pumped) | C12: m3 | D12: 170 | E12: QS ESTIMATE
A13: P-PROPS | B13: Props & soffit formwork hire per pour (3 weeks) | C13: m2 | D13: 45 | E13: QS ESTIMATE
... A22: P-CRANE | B22: 25 t mobile crane with operator | C22: day | D22: 9500 | E22: QS ESTIMATE

Sheet Regions
A1: Region | B1: Factor | C1: Basis / note
A2: Gauteng (Johannesburg / Pretoria / Midrand) - BASE | B2: 1 | C2: Base — AECOM rates are Gauteng-based.
A3: Western Cape - Cape Town metro & Winelands | B3: 1.08 | C3: AECOM: WC and KZN upper-class residential significantly above Gauteng. QS ESTIMATE.
A4: Western Cape - Garden Route / other | B4: 1.04 | C4: QS ESTIMATE.
A5: KwaZulu-Natal - Durban / Umhlanga / Ballito | B5: 1.04 | C5: AECOM regional note. QS ESTIMATE.
A6: KwaZulu-Natal - inland / other | B6: 0.98 | C6: QS ESTIMATE.
A7: Eastern Cape - Gqeberha / East London metros | B7: 0.97 | C7: Lower labour cost, comparable materials. QS ESTIMATE.
A8: Eastern Cape - rural (Transkei / Karoo interior) | B8: 1.06 | C8: Lower labour offset by haulage, no readymix, supervision travel. QS ESTIMATE.
A9: Free State - Bloemfontein | B9: 0.95 | C9: QS ESTIMATE.
A10: Free State - rural | B10: 0.98 | C10: QS ESTIMATE.
A11: Mpumalanga - Mbombela / Emalahleni | B11: 0.97 | C11: QS ESTIMATE.
A12: Limpopo - Polokwane | B12: 0.95 | C12: QS ESTIMATE.
A13: Limpopo - rural / remote | B13: 1.03 | C13: QS ESTIMATE.
... A16: Northern Cape - remote (Upington / Springbok) | B16: 1.08 | C16: Long-haul materials. QS ESTIMATE.

Sheet Elemental
A1: ELEMENTAL / ORDER-OF-MAGNITUDE BENCHMARKS (R/m2 construction area, ex VAT)
A2: Source: AECOM Africa Property & Construction Cost Guide 2025/26 pp.55-63 (rates at 1 July 2025, Gauteng). Include appropriate building services; exclude site infrastructure, parking (unless listed), escalation, professional fees and VAT. Escalated and region-adjusted by formula.
A4: Building type | B4: Unit | C4: AECOM low (Jul 2025) | D4: AECOM high (Jul 2025) | E4: Low — Sep 2026, region | F4: High — Sep 2026, region | G4: Mid — Sep 2026, region
A5: RESIDENTIAL
A6: RDP housing | B6: m2 | C6: 3400 | D6: 3600 | E6: =C6*Escalation!$B$20*Settings!$B$4*Settings!$B$9 -> 3568.2607 | F6: =D6*Escalation!$B$20*Settings!$B$4*Settings!$B$9 -> 3778.1584 | G6: =AVERAGE(E6:F6) -> 3673.2096
A7: Low-cost housing | B7: m2 | C7: 4300 | D7: 7400 | E7: =C7*Escalation!$B$20*Settings!$B$4*Settings!$B$9 -> 4512.8004 | F7: =D7*Escalation!$B$20*Settings!$B$4*Settings!$B$9 -> 7766.2146 | G7: =AVERAGE(E7:F7) -> 6139.5075
A8: Private dwelling — economic | B8: m2 | C8: 7920 | D8: 7920 | E8: =C8*Escalation!$B$20*Settings!$B$4*Settings!$B$9 -> 8311.9486 | F8: =D8*Escalation!$B$20*Settings!$B$4*Settings!$B$9 -> 8311.9486 | G8: =AVERAGE(E8:F8) -> 8311.9486
A9: Private dwelling — standard | B9: m2 | C9: 9850 | D9: 9850 | E9: =C9*Escalation!$B$20*Settings!$B$4*Settings!$B$9 -> 10337.461 | F9: =D9*Escalation!$B$20*Settings!$B$4*Settings!$B$9 -> 10337.461 | G9: =AVERAGE(E9:F9) -> 10337.461
A10: Private dwelling — middle-class | B10: m2 | C10: 11830 | D10: 11830 | E10: =C10*Escalation!$B$20*Settings!$B$4*Settings!$B$9 -> 12415.448 | F10: =D10*Escalation!$B$20*Settings!$B$4*Settings!$B$9 -> 12415.448 | G10: =AVERAGE(E10:F10) -> 12415.448
A11: Private dwelling — luxury | B11: m2 | C11: 16350 | D11: 16350 | E11: =C11*Escalation!$B$20*Settings!$B$4*Settings!$B$9 -> 17159.136 | F11: =D11*Escalation!$B$20*Settings!$B$4*Settings!$B$9 -> 17159.136 | G11: =AVERAGE(E11:F11) -> 17159.136
A12: Private dwelling — exclusive | B12: m2 | C12: 26450 | D12: 26450 | E12: =C12*Escalation!$B$20*Settings!$B$4*Settings!$B$9 -> 27758.97 | F12: =D12*Escalation!$B$20*Settings!$B$4*Settings!$B$9 -> 27758.97 | G12: =AVERAGE(E12:F12) -> 27758.97
A13: Private dwelling — super luxury | B13: m2 | C13: 38000 | D13: 80000 | E13: =C13*Escalation!$B$20*Settings!$B$4*Settings!$B$9 -> 39880.561 | F13: =D13*Escalation!$B$20*Settings!$B$4*Settings!$B$9 -> 83959.076 | G13: =AVERAGE(E13:F13) -> 61919.819
A14: Outbuildings — standard | B14: m2 | C14: 7400 | D14: 7400 | E14: =C14*Escalation!$B$20*Settings!$B$4*Settings!$B$9 -> 7766.2146 | F14: =D14*Escalation!$B$20*Settings!$B$4*Settings!$B$9 -> 7766.2146 | G14: =AVERAGE(E14:F14) -> 7766.2146
A15: Outbuildings — luxury | B15: m2 | C15: 10400 | D15: 10400 | E15: =C15*Escalation!$B$20*Settings!$B$4*Settings!$B$9 -> 10914.68 | F15: =D15*Escalation!$B$20*Settings!$B$4*Settings!$B$9 -> 10914.68 | G15: =AVERAGE(E15:F15) -> 10914.68
A16: Simple low-rise apartment block | B16: m2 | C16: 10300 | D16: 14300 | E16: =C16*Escalation!$B$20*Settings!$B$4*Settings!$B$9 -> 10809.731 | F16: =D16*Escalation!$B$20*Settings!$B$4*Settings!$B$9 -> 15007.685 | G16: =AVERAGE(E16:F16) -> 12908.708
A17: Duplex townhouse — economic | B17: m2 | C17: 10300 | D17: 14700 | E17: =C17*Escalation!$B$20*Settings!$B$4*Settings!$B$9 -> 10809.731 | F17: =D17*Escalation!$B$20*Settings!$B$4*Settings!$B$9 -> 15427.48 | G17: =AVERAGE(E17:F17) -> 13118.606
... A30: Tennis court — standard | B30: no | C30: 710000 | D30: 710000 | E30: =C30*Escalation!$B$20*Settings!$B$4*Settings!$B$9 -> 745136.8 | F30: =D30*Escalation!$B$20*Settings!$B$4*Settings!$B$9 -> 745136.8 | G30: =AVERAGE(E30:F30) -> 745136.8
A31: COMMERCIAL / RETAIL
A32: Low-rise office park, standard | B32: m2 | C32: 11300 | D32: 13900 | E32: =C32*Escalation!$B$20*Settings!$B$4*Settings!$B$9 -> 11859.22 | F32: =D32*Escalation!$B$20*Settings!$B$4*Settings!$B$9 -> 14587.89 | G32: =AVERAGE(E32:F32) -> 13223.555
A33: Low-rise office park, prestige | B33: m2 | C33: 14600 | D33: 21700 | E33: =C33*Escalation!$B$20*Settings!$B$4*Settings!$B$9 -> 15322.531 | F33: =D33*Escalation!$B$20*Settings!$B$4*Settings!$B$9 -> 22773.899 | G33: =AVERAGE(E33:F33) -> 19048.215
A34: High-rise office, standard | B34: m2 | C34: 16400 | D34: 21700 | E34: =C34*Escalation!$B$20*Settings!$B$4*Settings!$B$9 -> 17211.611 | F34: =D34*Escalation!$B$20*Settings!$B$4*Settings!$B$9 -> 22773.899 | G34: =AVERAGE(E34:F34) -> 19992.755
A35: High-rise office, prestige | B35: m2 | C35: 21700 | D35: 27400 | E35: =C35*Escalation!$B$20*Settings!$B$4*Settings!$B$9 -> 22773.899 | F35: =D35*Escalation!$B$20*Settings!$B$4*Settings!$B$9 -> 28755.984 | G35: =AVERAGE(E35:F35) -> 25764.942
A36: Local convenience centre <= 5,000 m2 | B36: m2 | C36: 11100 | D36: 14600 | E36: =C36*Escalation!$B$20*Settings!$B$4*Settings!$B$9 -> 11649.322 | F36: =D36*Escalation!$B$20*Settings!$B$4*Settings!$B$9 -> 15322.531 | G36: =AVERAGE(E36:F36) -> 13485.927
A37: Neighbourhood centre 5,000-12,000 m2 | B37: m2 | C37: 12100 | D37: 16100 | E37: =C37*Escalation!$B$20*Settings!$B$4*Settings!$B$9 -> 12698.81 | F37: =D37*Escalation!$B$20*Settings!$B$4*Settings!$B$9 -> 16896.764 | G37: =AVERAGE(E37:F37) -> 14797.787
A38: Community centre 12,000-25,000 m2 | B38: m2 | C38: 13300 | D38: 17100 | E38: =C38*Escalation!$B$20*Settings!$B$4*Settings!$B$9 -> 13958.196 | F38: =D38*Escalation!$B$20*Settings!$B$4*Settings!$B$9 -> 17946.253 | G38: =AVERAGE(E38:F38) -> 15952.225
A39: Studios (dance, art exhibition) | B39: m2 | C39: 19500 | D39: 28000 | E39: =C39*Escalation!$B$20*Settings!$B$4*Settings!$B$9 -> 20465.025 | F39: =D39*Escalation!$B$20*Settings!$B$4*Settings!$B$9 -> 29385.677 | G39: =AVERAGE(E39:F39) -> 24925.351
A40: Conference centre, international standard | B40: m2 | C40: 36000 | D40: 46000 | E40: =C40*Escalation!$B$20*Settings!$B$4*Settings!$B$9 -> 37781.584 | F40: =D40*Escalation!$B$20*Settings!$B$4*Settings!$B$9 -> 48276.469 | G40: =AVERAGE(E40:F40) -> 43029.027
A41: INDUSTRIAL
A42: Warehouse, steel frame & cladding (light duty) | B42: m2 | C42: 5800 | D42: 7400 | E42: =C42*Escalation!$B$20*Settings!$B$4*Settings!$B$9 -> 6087.033 | F42: =D42*Escalation!$B$20*Settings!$B$4*Settings!$B$9 -> 7766.2146 | G42: =AVERAGE(E42:F42) -> 6926.6238
A43: Warehouse, brick to ceiling + cladding (heavy duty) | B43: m2 | C43: 6500 | D43: 9300 | E43: =C43*Escalation!$B$20*Settings!$B$4*Settings!$B$9 -> 6821.675 | F43: =D43*Escalation!$B$20*Settings!$B$4*Settings!$B$9 -> 9760.2426 | G43: =AVERAGE(E43:F43) -> 8290.9588
A44: Admin offices / ablution / change block | B44: m2 | C44: 10500 | D44: 13400 | E44: =C44*Escalation!$B$20*Settings!$B$4*Settings!$B$9 -> 11019.629 | F44: =D44*Escalation!$B$20*Settings!$B$4*Settings!$B$9 -> 14063.145 | G44: =AVERAGE(E44:F44) -> 12541.387
A45: Cold storage | B45: m2 | C45: 19600 | D45: 27900 | E45: =C45*Escalation!$B$20*Settings!$B$4*Settings!$B$9 -> 20569.974 | F45: =D45*Escalation!$B$20*Settings!$B$4*Settings!$B$9 -> 29280.728 | G45: =AVERAGE(E45:F45) -> 24925.351
A46: PARKING
A47: Parking on grade incl landscaping | B47: m2 | C47: 800 | D47: 1000 | E47: =C47*Escalation!$B$20*Settings!$B$4*Settings!$B$9 -> 839.59076 | F47: =D47*Escalation!$B$20*Settings!$B$4*Settings!$B$9 -> 1049.4885 | G47: =AVERAGE(E47:F47) -> 944.53961
A48: Structured parking | B48: m2 | C48: 5500 | D48: 6100 | E48: =C48*Escalation!$B$20*Settings!$B$4*Settings!$B$9 -> 5772.1865 | F48: =D48*Escalation!$B$20*Settings!$B$4*Settings!$B$9 -> 6401.8796 | G48: =AVERAGE(E48:F48) -> 6087.033
A49: Semi-basement parking | B49: m2 | C49: 6100 | D49: 8300 | E49: =C49*Escalation!$B$20*Settings!$B$4*Settings!$B$9 -> 6401.8796 | F49: =D49*Escalation!$B$20*Settings!$B$4*Settings!$B$9 -> 8710.7542 | G49: =AVERAGE(E49:F49) -> 7556.3169
A50: Basement parking | B50: m2 | C50: 6500 | D50: 11300 | E50: =C50*Escalation!$B$20*Settings!$B$4*Settings!$B$9 -> 6821.675 | F50: =D50*Escalation!$B$20*Settings!$B$4*Settings!$B$9 -> 11859.22 | G50: =AVERAGE(E50:F50) -> 9340.4473
A51: SOCIAL
A52: Primary school | B52: m2 | C52: 9300 | D52: 10700 | E52: =C52*Escalation!$B$20*Settings!$B$4*Settings!$B$9 -> 9760.2426 | F52: =D52*Escalation!$B$20*Settings!$B$4*Settings!$B$9 -> 11229.526 | G52: =AVERAGE(E52:F52) -> 10494.885
A53: Secondary school | B53: m2 | C53: 11100 | D53: 11900 | E53: =C53*Escalation!$B$20*Settings!$B$4*Settings!$B$9 -> 11649.322 | F53: =D53*Escalation!$B$20*Settings!$B$4*Settings!$B$9 -> 12488.913 | G53: =AVERAGE(E53:F53) -> 12069.117
...

Sheet Escalation
A1: BUILDING COST INDICES (Jan 2020 = 100)
A2: Source: AECOM Africa Property & Construction Cost Guide 2025/26, Section 7 — BER (Stellenbosch) tender price index and Stats SA P0151 CPAP Work Group 181. 2026-2029 are forecasts.
A4: Year (Jan) | B4: BER tender index | C4: BER y-o-y | D4: CPAP WG181 index | E4: CPAP y-o-y | F4: Tender Market Indicator
A5: 2020 | B5: 100 | D5: 100 | F5: 1
A6: 2021 | B6: 102.4 | C6: 0.024 | D6: 106 | E6: 0.06 | F6: 0.97
A7: 2022 | B7: 108.1 | C7: 0.056 | D7: 120.9 | E7: 0.141 | F7: 0.89
A8: 2023 | B8: 119.1 | C8: 0.101 | D8: 128.4 | E8: 0.062 | F8: 0.93
A9: 2024 | B9: 136.7 | C9: 0.148 | D9: 135.1 | E9: 0.052 | F9: 1.01
A10: 2025 | B10: 145.7 | C10: 0.066 | D10: 137.8 | E10: 0.02 | F10: 1.06
A11: 2026 | B11: 150.9 | C11: 0.036 | D11: 144 | E11: 0.045 | F11: 1.05
A12: 2027 | B12: 158 | C12: 0.047 | D12: 150.7 | E12: 0.046 | F12: 1.05
A13: 2028 | B13: 166.9 | C13: 0.056 | D13: 157.3 | E13: 0.044 | F13: 1.06
A14: 2029 | B14: 176.7 | C14: 0.059 | D14: 164.2 | E14: 0.044 | F14: 1.08
A17: Escalation of AECOM 1 July 2025 benchmarks to library base date (Sep 2026)
A18: Jul 2025 -> Jan 2026 (6 months at 2026 y-o-y) | B18: =(1+C11)^(6/12) -> 1.0178409
A19: Jan 2026 -> Sep 2026 (8 months at 2027 y-o-y) | B19: =(1+C12)^(8/12) -> 1.0310929
A20: Factor AECOM Jul-2025 -> Sep-2026 | B20: =B18*B19 -> 1.0494885

Sheet Calibration
A1: CALIBRATION — library sell rates vs published 2026 SA market ranges
A2: Consumer guides quote builder prices that usually include higher OH&P and sometimes VAT, so library sell rates (17% margin, ex VAT) are expected to sit low-to-mid in range.
A4: Code | B4: Item | C4: Compared | D4: Market low | E4: Market high | F4: Library sell | G4: Position | H4: Source
A5: MS01 | B5: Half-brick wall | C5: Labour only | D5: 150 | E5: 270 | F5: =INDEX(Rates!$F:$F,MATCH(A5,Rates!$A:$A,0))*Settings!$B$4*Settings!$B$9*(1+Settings!$B$10) -> 165.21111 | G5: =IF(F5<D5,"Below range",IF(F5>E5,"Above range","In range")) -> In range | H5: sapropertytools.co.za bricklaying calculator, June 2026
A6: MS02 | B6: One-brick wall | C6: Labour only | D6: 300 | E6: 510 | F6: =INDEX(Rates!$F:$F,MATCH(A6,Rates!$A:$A,0))*Settings!$B$4*Settings!$B$9*(1+Settings!$B$10) -> 310.98563 | G6: =IF(F6<D6,"Below range",IF(F6>E6,"Above range","In range")) -> In range | H6: sapropertytools.co.za, June 2026
A7: TL01 | B7: Floor tiling | C7: Labour only | D7: 110 | E7: 200 | F7: =INDEX(Rates!$F:$F,MATCH(A7,Rates!$A:$A,0))*Settings!$B$4*Settings!$B$9*(1+Settings!$B$10) -> 130.63778 | G7: =IF(F7<D7,"Below range",IF(F7>E7,"Above range","In range")) -> In range | H7: sapropertytools.co.za tiling calculator, June 2026
A8: TL03 | B8: Wall tiling | C8: Labour only | D8: 140 | E8: 240 | F8: =INDEX(Rates!$F:$F,MATCH(A8,Rates!$A:$A,0))*Settings!$B$4*Settings!$B$9*(1+Settings!$B$10) -> 163.29722 | G8: =IF(F8<D8,"Below range",IF(F8>E8,"Above range","In range")) -> In range | H8: sapropertytools.co.za, June 2026
A9: PL01 | B9: Two-coat internal plaster | C9: Labour only | D9: 85 | E9: 130 | F9: =INDEX(Rates!$F:$F,MATCH(A9,Rates!$A:$A,0))*Settings!$B$4*Settings!$B$9*(1+Settings!$B$10) -> 87.464707 | G9: =IF(F9<D9,"Below range",IF(F9>E9,"Above range","In range")) -> In range | H9: sapropertytools.co.za plastering calculator, June 2026
A10: PL01 | B10: Two-coat internal plaster | C10: All-in | D10: 90 | E10: 160 | F10: =INDEX(Rates!$T:$T,MATCH(A10,Rates!$A:$A,0)) -> 111.59069 | G10: =IF(F10<D10,"Below range",IF(F10>E10,"Above range","In range")) -> In range | H10: sapropertytools.co.za plastering & painting guide, July 2026
A11: PT01 | B11: Interior painting | C11: Labour only | D11: 25 | E11: 60 | F11: =INDEX(Rates!$F:$F,MATCH(A11,Rates!$A:$A,0))*Settings!$B$4*Settings!$B$9*(1+Settings!$B$10) -> 29.100778 | G11: =IF(F11<D11,"Below range",IF(F11>E11,"Above range","In range")) -> In range | H11: sapropertytools.co.za, July 2026
A12: RF01 | B12: Roof trusses excl covering | C12: All-in | D12: 250 | E12: 650 | F12: =INDEX(Rates!$T:$T,MATCH(A12,Rates!$A:$A,0)) -> 522.62416 | G12: =IF(F12<D12,"Below range",IF(F12>E12,"Above range","In range")) -> In range | H12: completeroofing.co.za, Feb 2026
A13: RF04 | B13: Concrete tile covering | C13: All-in | D13: 500 | E13: 800 | F13: =INDEX(Rates!$T:$T,MATCH(A13,Rates!$A:$A,0)) -> 445.72591 | G13: =IF(F13<D13,"Below range",IF(F13>E13,"Above range","In range")) -> Below range | H13: thehandymanjohannesburg.co.za, 2026 (JHB, typically incl VAT)
A14: RF06 | B14: IBR sheeting covering | C14: All-in | D14: 150 | E14: 350 | F14: =INDEX(Rates!$T:$T,MATCH(A14,Rates!$A:$A,0)) -> 313.9548 | G14: =IF(F14<D14,"Below range",IF(F14>E14,"Above range","In range")) -> In range | H14: servicelinksa.co.za, Mar 2026 (covering only)

Sheet Sources
A1: SOURCES
A3: AECOM Africa Property & Construction Cost Guide 2025/26 (36th ed.) — SA building cost rates, services rates, BER/CPAP indices | B3: https://cdn.ymaws.com/www.asaqs.co.za/resource/resmgr/4_resources/free_resources/other_publications/aecom_africa_cost_guide_2025.pdf
A4: National Minimum Wage R30.23/hr from 1 March 2026 (GN R.7083, Gazette 54075) | B4: https://www.sanews.gov.za/south-africa/national-minimum-wage-rise-r3023-hour-march
A5: Bargaining Council for the Building Industry, Cape of Good Hope — Main Agreement cl.18 minimum wages (to 31 Oct 2026) | B5: https://www.acts.co.za/labour/r6498_18__minimum_basic_wages
A6: BCCEI Civil Engineering task-grade minimum wages (WageIndicator, 2026) | B6: https://wageindicator.org/en-za/work-in-south-africa/minimum-wage/6228-civil-engineering-sector
A7: SA Property Tools — 2026 bricklaying / tiling / plastering labour rate benchmarks | B7: https://sapropertytools.co.za/calculators/artisan/bricklaying-labour.html
A8: SA Property Tools — Plastering & painting cost guide 2026 | B8: https://sapropertytools.co.za/blog/plastering-painting-guide-sa.html
A9: Handyman Johannesburg — Building material prices 2026 (cement, sand, stone, readymix, bricks) | B9: https://www.thehandymanjohannesburg.co.za/building-material-prices/
A10: Complete Roofing — roof truss prices per m2 (2026) | B10: https://completeroofing.co.za/blog/roof-trusses-prices-per-m2/
A11: PPC mix guidance via South Africa Facts concrete calculator (Aug 2026) | B11: https://southafricafacts.co.za/concrete-mortar-calculator-south-africa/
A12: Stats SA P0151 Contract Price Adjustment Provisions indices (for escalation claims) | B12: https://www.statssa.gov.za
A13: ASAQS Standard System of Measuring Building Work (trade order used for descriptions) | B13: https://www.asaqs.co.za
